<?xml version="1.0"?>
<robot name="openspot" xmlns:xacro="http://ros.org/wiki/xacro">
  <xacro:property name="body_length" value="0.58"/>
  <xacro:property name="body_width" value="0.132"/>
  <xacro:property name="body_height" value="0.099"/>
  <xacro:property name="body_mass" value="15"/>
  <xacro:property name="abad_mass" value="2"/>
  <xacro:property name="abad_radius" value="0.05"/>
  <xacro:property name="abad_height" value="0.084"/>
  <xacro:property name="hip_mass" value="1"/>
  <xacro:property name="hip_length" value="0.284"/>
  <xacro:property name="hip_width" value="0.03"/>
  <xacro:property name="knee_mass" value="1"/>
  <xacro:property name="knee_length" value="0.284"/>
  <xacro:property name="knee_width" value="0.03"/>
  <xacro:property name="max_effort" value="40.1"/>

  <!-- lrsign : 1(left), -1(right); fhsign : 1(front), -1(hind) -->
  <xacro:macro name="leg" params="legid lrsign fhsign">
    <joint name="${legid}_abad_joint" type="revolute">
      <parent link="base_link"/>
      <child link="${legid}_abad_link"/>
      <axis xyz="1 0 0"/>
      <xacro:if value="${lrsign==1}">
      <limit effort="${max_effort}" velocity="10" upper="${0.75*pi}" lower="${-0.25*pi}"/>
      </xacro:if>
      <xacro:if value="${lrsign==-1}">
      <limit effort="${max_effort}" velocity="10" upper="${0.25*pi}" lower="${-0.75*pi}"/>
      </xacro:if>
      <origin xyz="${fhsign*body_length*0.5} ${lrsign*body_width*0.5} 0" rpy="0 0 0"/>
    </joint>
    <link name="${legid}_abad_link">
      <visual>
        <origin xyz="${fhsign*abad_radius} ${lrsign*abad_height*0.25} 0" rpy="${pi*0.5} 0 0"/>
        <geometry>
          <cylinder radius="${abad_radius}" length="${abad_height}"/>
        </geometry>
      </visual>
      <collision>
        <origin xyz="${fhsign*abad_radius} ${lrsign*abad_height*0.25} 0" rpy="${pi*0.5} 0 0"/>
        <geometry>
          <cylinder radius="${abad_radius}" length="${abad_height}"/>
        </geometry>
      </collision>
      <inertial>
        <origin xyz="${fhsign*abad_radius} ${lrsign*abad_height*0.25} 0" rpy="0 0 0"/>
        <mass value="${abad_mass}"/>
        <inertia ixx="0.002426" ixy="0" ixz="0" iyy="0.0025" iyz="0" izz="0.002426"/>
      </inertial>
    </link>
    <joint name="${legid}_hip_joint" type="revolute">
      <parent link="${legid}_abad_link"/>
      <child link="${legid}_hip_link"/>
      <axis xyz="0 1 0"/>
      <limit effort="${max_effort}" velocity="10" upper="${0.75*pi}" lower="${0.167*pi}"/>
      <origin xyz="${fhsign*abad_radius} ${lrsign*abad_height*0.75} 0" rpy="0 0 0"/>
    </joint>
    <link name="${legid}_hip_link">
      <visual>
        <origin xyz="0 ${lrsign*hip_width*0.5} ${-hip_length*0.5}" rpy="0 0 0"/>
        <geometry>
          <box size="0.035 ${hip_width} ${hip_length}"/>
        </geometry>
      </visual>
      <collision>
        <origin xyz="0 ${lrsign*hip_width*0.5} ${-hip_length*0.5}" rpy="0 0 0"/>
        <geometry>
          <box size="0.035 ${hip_width} ${hip_length}"/>
        </geometry>
      </collision>
      <inertial>
        <origin xyz="0 ${lrsign*hip_width*0.5} ${-hip_length*0.5}" rpy="0 0 0"/>
        <mass value="${hip_mass}"/>
        <inertia ixx="0.006796" ixy="0" ixz="0" iyy="0.006823" iyz="0" izz="0.000177"/>
      </inertial>
    </link>
    <joint name="${legid}_knee_joint" type="revolute">
      <parent link="${legid}_hip_link"/>
      <child link="${legid}_knee_link"/>
      <axis xyz="0 1 0"/>
      <limit effort="${max_effort}" velocity="10" upper="${-0.167*pi}" lower="${-0.94*pi}"/>
      <origin xyz="0 ${lrsign*hip_width*0.5} ${-hip_length}" rpy="0 0 0"/>
    </joint>
    <link name="${legid}_knee_link">
      <visual>
        <origin xyz="0 0 ${-knee_length*0.5}" rpy="0 0 0"/>
        <geometry>
          <box size="0.035 ${knee_width} ${knee_length}"/>
        </geometry>
      </visual>
      <collision>
        <origin xyz="0 0 ${-knee_length*0.5}" rpy="0 0 0"/>
        <geometry>
          <box size="0.035 ${knee_width} ${knee_length}"/>
        </geometry>
      </collision>
      <inertial>
        <origin xyz="0 0 ${-knee_length*0.5}" rpy="0 0 0"/>
        <mass value="${knee_mass}"/>
        <inertia ixx="0.006796" ixy="0" ixz="0" iyy="0.006823" iyz="0" izz="0.000177"/>
      </inertial>
    </link>
    <link name="${legid}_foot_link">
      <visual>
        <origin xyz="0 0 0" rpy="0 0 0"/>
        <geometry>
          <sphere radius="0.03"/>
        </geometry>
      </visual>
      <collision>
        <origin xyz="0 0 0" rpy="0 0 0"/>
        <geometry>
          <sphere radius="0.03"/>
        </geometry>
      </collision>
    </link>
    <joint name="${legid}_foot_joint" type="fixed">
      <parent link="${legid}_knee_link"/>
      <child link="${legid}_foot_link"/>
      <origin xyz="0 0 ${-knee_length}" rpy="0 0 0"/>
    </joint>
  </xacro:macro>

  <link name="base_footprint"/>
  <joint name="base_joint" type="fixed">
    <parent link="base_footprint"/>
    <child link="base_link"/>
    <origin xyz="0 0 ${body_height/2}" rpy="0 0 0"/>
  </joint>
  <link name="base_link">
    <visual>
      <origin xyz="0 0 0" rpy="0 0 0"/>
      <geometry>
        <box size="${body_length} ${body_width} ${body_height}"/>
      </geometry>
    </visual>
    <collision>
      <origin xyz="0 0 0" rpy="0 0 0"/>
      <geometry>
        <box size="${body_length} ${body_width} ${body_height}"/>
      </geometry>
    </collision>
    <inertial>
      <origin xyz="0 0 0" rpy="0 0 0"/>
      <mass value="${body_mass}"/>
      <inertia ixx="0.0567188" ixy="0" ixz="0" iyy="0.721252" iyz="0" izz="0.737133"/>
    </inertial>
  </link>

  <xacro:leg legid="fr" lrsign="-1" fhsign="1"/>
  <xacro:leg legid="hr" lrsign="-1" fhsign="-1"/>
  <xacro:leg legid="fl" lrsign="1" fhsign="1"/>
  <xacro:leg legid="hl" lrsign="1" fhsign="-1"/>

  <link name="imu_link">
  </link>
  <joint name="joint_imu" type="fixed">
    <parent link="base_link"/>
    <child link="imu_link"/>
    <origin xyz="0 0 0" rpy="0 0 0"/>
  </joint>

  <link name="lidar_link">
    <inertial>
      <origin xyz="0 0 0" rpy="0 0 0"/>
      <mass value="0.125"/>
      <inertia ixx="0.001"  ixy="0"  ixz="0" iyy="0.001" iyz="0" izz="0.001" />
    </inertial>

    <collision>
      <origin xyz="0 0 0" rpy="0 0 0"/>
      <geometry>
         <cylinder radius="0.0508" length="0.05"/>
      </geometry>
    </collision>

    <visual>
      <origin xyz="0 0 0" rpy="0 0 0"/>
      <geometry>
         <cylinder radius="0.0508" length="0.05"/>
      </geometry>
    </visual>
  </link>

  <joint name="lidar_joint" type="fixed">
    <parent link="base_link"/>
    <child link="lidar_link"/>
    <origin xyz="0 0 ${body_height/2 + 0.025}" rpy="0 0 0"/>
  </joint>

  <!-- Gazebo -->
  <gazebo reference="imu_link">
    <sensor name="imu_sensor" type="imu">
      <plugin filename="libgazebo_ros_imu_sensor.so" name="imu_plugin">
        <ros>
          <remapping>~/out:=imu</remapping>
        </ros>
        <initial_orientation_as_reference>false</initial_orientation_as_reference>
      </plugin>
      <always_on>true</always_on>
      <update_rate>1000</update_rate>
      <visualize>true</visualize>
     <imu>
     	<angular_velocity>
     	  <x>
     	    <noise type="gaussian">
              <mean>0.0</mean>
              <stddev>2e-4</stddev>
              <bias_mean>0.0000075</bias_mean>
              <bias_stddev>0.0000008</bias_stddev>
            </noise>
          </x>
          <y>
            <noise type="gaussian">
              <mean>0.0</mean>
              <stddev>2e-4</stddev>
              <bias_mean>0.0000075</bias_mean>
              <bias_stddev>0.0000008</bias_stddev>
            </noise>
          </y>
          <z>
            <noise type="gaussian">
              <mean>0.0</mean>
              <stddev>2e-4</stddev>
              <bias_mean>0.0000075</bias_mean>
              <bias_stddev>0.0000008</bias_stddev>
            </noise>
          </z>
        </angular_velocity>
        <linear_acceleration>
          <x>
            <noise type="gaussian">
              <mean>0.0</mean>
              <stddev>1.7e-2</stddev>
              <bias_mean>0.1</bias_mean>
              <bias_stddev>0.001</bias_stddev>
            </noise>
          </x>
          <y>
            <noise type="gaussian">
              <mean>0.0</mean>
              <stddev>1.7e-2</stddev>
              <bias_mean>0.1</bias_mean>
              <bias_stddev>0.001</bias_stddev>
            </noise>
          </y>
          <z>
            <noise type="gaussian">
              <mean>0.0</mean>
              <stddev>1.7e-2</stddev>
              <bias_mean>0.1</bias_mean>
              <bias_stddev>0.001</bias_stddev>
            </noise>
          </z>
        </linear_acceleration>
      </imu>
    </sensor>
  </gazebo>

  <gazebo reference="lidar_link">
    <sensor name="lidar" type="ray">
      <always_on>true</always_on>
      <visualize>true</visualize>
      <update_rate>5</update_rate>
      <ray>
        <scan>
          <horizontal>
            <samples>360</samples>
            <resolution>1.000000</resolution>
            <min_angle>0.000000</min_angle>
            <max_angle>6.280000</max_angle>
          </horizontal>
        </scan>
        <range>
          <min>0.120000</min>
          <max>3.5</max>
          <resolution>0.015000</resolution>
        </range>
        <noise>
          <type>gaussian</type>
          <mean>0.0</mean>
          <stddev>0.01</stddev>
        </noise>
      </ray>
      <plugin name="scan" filename="libgazebo_ros_ray_sensor.so">
        <ros>
          <remapping>~/out:=scan</remapping>
        </ros>
        <output_type>sensor_msgs/LaserScan</output_type>
        <frame_name>lidar_link</frame_name>
      </plugin>
    </sensor>
  </gazebo>

  <gazebo>
    <plugin name='openspot_drive' filename='libopenspot_sim.so'>
      <publish_odom>true</publish_odom>
      <publish_odom_tf>true</publish_odom_tf>
      <odometry_frame>odom</odometry_frame>
      <robot_base_frame>base_footprint</robot_base_frame>
      <spotng>
        <log>
          <level>info</level>
        </log>
        <model>
          <body_length>${body_length}</body_length>
          <body_width>${body_width}</body_width>
          <body_height>${body_height}</body_height>

          <mass_body>${body_mass}</mass_body>
          <mass_abad>${abad_mass}</mass_abad>
          <mass_hip>${hip_mass}</mass_hip>
          <mass_knee>${knee_mass}</mass_knee>
          <mass_total>${body_mass + (abad_mass + hip_mass + knee_mass) * 4}</mass_total>

          <link_length_abad>${abad_height*0.75 + hip_width}</link_length_abad>
          <link_length_hip>${hip_length}</link_length_hip>
          <link_length_knee>${knee_length}</link_length_knee>

          <basic_locomotion_height>0.4</basic_locomotion_height>
          <fast_locomotion_height>0.34</fast_locomotion_height>
          <foot_offsetx>-0.03</foot_offsetx>
          <foot_offsety>-0.02</foot_offsety>

          <location_abad_fl>0.29 0.066 0.0</location_abad_fl>
          <location_hip_fl>0.05 0.093 0.0</location_hip_fl>
          <location_knee_fl>0 0 -0.284</location_knee_fl>

          <com_body>0 0 0</com_body>
          <com_abad_fl>0.05 0.021 0.0</com_abad_fl>
          <com_hip_fl>0 0 -0.142</com_hip_fl>
          <com_knee_fl>0 0 -0.142</com_knee_fl>

          <inertia_body>0.0567188 0 0 0 0.721252 0 0 0 0.737133</inertia_body>
          <inertia_abad>0.002426 0 0 0 0.0025 0 0 0 0.002426</inertia_abad>
          <inertia_hip>0.00679633 0 0 0 0.00682342 0 0 0 0.000177083</inertia_hip>
          <inertia_knee>0.00679633 0 0 0 0.00682342 0 0 0 0.000177083</inertia_knee>
          <inertia_total>0.07487 0 0 0 2.1566 0 0 0 2.1775</inertia_total>

          <max_com_height>0.55</max_com_height>
          <max_body_roll>0.523</max_body_roll>
          <max_body_pitch>0.785</max_body_pitch>
          <max_body_yaw>0.523</max_body_yaw>
        </model>
        <ctrl>
          <mpc_iters>15</mpc_iters>
          <mpc_weights>1.25 1.25 10 2 2 50 0 0 0.3 1.5 1.5 0.2 0</mpc_weights>
          <footskd_bonus_swing>0</footskd_bonus_swing>
          <footskd_vkp>0.1</footskd_vkp>
          <kp_bodypos>100 100 100</kp_bodypos>
          <kd_bodypos>10 10 20</kd_bodypos>
          <kp_bodyori>100 100 100</kp_bodyori>
          <kd_bodyori>10 10 10</kd_bodyori>
          <kp_foot>500 500 500</kp_foot>
          <kd_foot>60 60 60</kd_foot>
          <kp_joint>3 3 3</kp_joint>
          <kd_joint>1.0 0.2 0.2</kd_joint>
          <kp_jpos>80 80 80</kp_jpos>
          <kd_jpos>1 1 1</kd_jpos>
          <jpos_init>-0.0 1.4 -2.7 0.0 1.4 -2.7 -0.0 1.4 -2.7 0.0 1.4 -2.7</jpos_init>
          <jpos_fold>-0.0 1.4 -2.7 0.0 1.4 -2.7 -0.0 1.4 -2.7 0.0 1.4 -2.7</jpos_fold>
          <jpos_stand>-0.0 0.8 -1.6 0.0 0.8 -1.6 -0.0 0.9 -1.5 0.0 0.9 -1.5</jpos_stand>
          <jpos_rolling>1.5 1.6 -2.77 1.3 3.1 -2.77 1.5 1.6 -2.77 1.3 3.1 -2.77</jpos_rolling>
          <max_trot_lvel_x>1.8</max_trot_lvel_x>
          <min_trot_lvel_x>-0.8</min_trot_lvel_x>
          <max_trot_lvel_y>0.4</max_trot_lvel_y>
          <max_trot_avel_z>0.8</max_trot_avel_z>
        </ctrl>
      </spotng>
    </plugin>
  </gazebo>

  <gazebo>
    <plugin name="gazebo_ros_joint_state_publisher"
        filename="libgazebo_ros_joint_state_publisher.so">
      <!-- Update rate in Hertz -->
      <update_rate>2</update_rate>
      <!-- Name of joints in the model whose states will be published. -->
      <joint_name>fr_abad_joint</joint_name>
      <joint_name>fr_hip_joint</joint_name>
      <joint_name>fr_knee_joint</joint_name>
      <joint_name>hr_abad_joint</joint_name>
      <joint_name>hr_hip_joint</joint_name>
      <joint_name>hr_knee_joint</joint_name>
      <joint_name>fl_abad_joint</joint_name>
      <joint_name>fl_hip_joint</joint_name>
      <joint_name>fl_knee_joint</joint_name>
      <joint_name>hl_abad_joint</joint_name>
      <joint_name>hl_hip_joint</joint_name>
      <joint_name>hl_knee_joint</joint_name>
    </plugin>
  </gazebo>

</robot>
